{"name": "Проверка https://dev-api.getprime.pro/api/v1/auth", "status": "failed", "statusDetails": {"message": "AssertionError: Проверка не прошла\nassert 'Вы не авторизованы. Пожалуйста, выполните вход и повторите попытку.' == 'Вы не авторизованы. Пожалуйста, выполните вход и повториkkте попытку.'\n  \n  - Вы не авторизованы. Пожалуйста, выполните вход и повториkkте попытку.\n  ?                                                         --\n  + Вы не авторизованы. Пожалуйста, выполните вход и повторите попытку.", "trace": "self = <test_api.TestApiGet object at 0x000001D4CDFFA9D0>\n\n    @pytest.mark.apitest\n    @allure.title(\"Проверка https://dev-api.getprime.pro/api/v1/auth\")\n    @allure.description(\"Невалидная проверка с передачей неверного ключа \")\n    def test_auth_wrong_key(self):\n        url = \"https://dev-api.getprime.pro/api/v1/auth\"\n        with allure.step(f\"Проверка {url} на код 401\"):\n            assert requests.post(url=url,\n                                 headers={'X-API-Key': \"invalid-api-key\"}).status_code == 401, \"Статус код не 401\"\n        response = (requests.post(url).json())\n        with allure.step(\n                f\"Проверка ответа на запрос в message. Ожидали текст 'Вы не авторизованы. Пожалуйста, выполните вход и повторите попытку.' а получили '{response['message']}'\"):\n>           assert response[\n                       'message'] == \"Вы не авторизованы. Пожалуйста, выполните вход и повториkkте попытку.\", \"Проверка не прошла\"\nE           AssertionError: Проверка не прошла\nE           assert 'Вы не авторизованы. Пожалуйста, выполните вход и повторите попытку.' == 'Вы не авторизованы. Пожалуйста, выполните вход и повториkkте попытку.'\nE             \nE             - Вы не авторизованы. Пожалуйста, выполните вход и повториkkте попытку.\nE             ?                                                         --\nE             + Вы не авторизованы. Пожалуйста, выполните вход и повторите попытку.\n\ntest_api.py:49: AssertionError"}, "description": "Невалидная проверка с передачей неверного ключа ", "steps": [{"name": "Проверка https://dev-api.getprime.pro/api/v1/auth на код 401", "status": "passed", "start": 1751966690560, "stop": 1751966690761}, {"name": "Проверка ответа на запрос в message. Ожидали текст 'Вы не авторизованы. Пожалуйста, выполните вход и повторите попытку.' а получили 'Вы не авторизованы. Пожалуйста, выполните вход и повторите попытку.'", "status": "failed", "statusDetails": {"message": "AssertionError: Проверка не прошла\nassert 'Вы не авторизованы. Пожалуйста, выполните вход и повторите попытку.' == 'Вы не авторизованы. Пожалуйста, выполните вход и повториkkте попытку.'\n  \n  - Вы не авторизованы. Пожалуйста, выполните вход и повториkkте попытку.\n  ?                                                         --\n  + Вы не авторизованы. Пожалуйста, выполните вход и повторите попытку.\n", "trace": "  File \"C:\\Users\\Qasquad1\\PycharmProjects\\GetPrime\\tests\\test_api.py\", line 49, in test_auth_wrong_key\n    assert response[\n"}, "start": 1751966690967, "stop": 1751966690970}], "start": 1751966690560, "stop": 1751966690970, "uuid": "c0a553cc-f22d-4c06-8abe-6c7ed08407d3", "historyId": "f6aad7747424500f0f55fb65296e0431", "testCaseId": "f6aad7747424500f0f55fb65296e0431", "fullName": "tests.test_api.TestApiGet#test_auth_wrong_key", "labels": [{"name": "tag", "value": "apitest"}, {"name": "parentSuite", "value": "tests"}, {"name": "suite", "value": "test_api"}, {"name": "subSuite", "value": "TestApiGet"}, {"name": "host", "value": "Robotek3000"}, {"name": "thread", "value": "3712-MainThread"}, {"name": "framework", "value": "pytest"}, {"name": "language", "value": "cpython3"}, {"name": "package", "value": "tests.test_api"}]}